[1m[31mERROR   [0m root:base_app.py:29 æ²¡æœ‰æ‰¾åˆ°è¿™ä¸ªå…ƒç´ 